Workbook

Sheet Gantt
A1: AYNI BANK — Diagrama de Gantt híbrido (PMBOK + Scrum)
A2: 14 de agosto – 13 de diciembre de 2026 · 17 semanas · Sprint 0 de 1 semana + 8 sprints de 2 semanas
A3: LEYENDA | G3: Fases de gestión (PMBOK) | V3: Sprints (timebox 2 semanas) | AK3: Épicas / bloques de valor | AZ3: Hitos | BO3: Revisiones externas
F4: =IF(F$6=TODAY(),"▼","") | G4: =IF(G$6=TODAY(),"▼","") -> ▼ | H4: =IF(H$6=TODAY(),"▼","") | I4: =IF(I$6=TODAY(),"▼","") | J4: =IF(J$6=TODAY(),"▼","") | K4: =IF(K$6=TODAY(),"▼","") | L4: =IF(L$6=TODAY(),"▼","") | M4: =IF(M$6=TODAY(),"▼","") | ... DW4: =IF(DW$6=TODAY(),"▼","")
A5: ID | B5: TAREA | C5: INICIO | D5: FIN | E5: DÍAS | F5: AGOSTO 2026 | X5: SETIEMBRE 2026 | BB5: OCTUBRE 2026 | CG5: NOVIEMBRE 2026 | DK5: DICIEMBRE 2026
F6: 46248 | G6: 46249 | H6: 46250 | I6: 46251 | J6: 46252 | K6: 46253 | L6: 46254 | M6: 46255 | N6: 46256 | O6: 46257 | P6: 46258 | Q6: 46259 | R6: 46260 | S6: 46261 | T6: 46262 | U6: 46263 | V6: 46264 | W6: 46265 | X6: 46266 | Y6: 46267 | Z6: 46268 | AA6: 46269 | AB6: 46270 | AC6: 46271 | AD6: 46272 | AE6: 46273 | AF6: 46274 | AG6: 46275 | AH6: 46276 | AI6: 46277 | AJ6: 46278 | AK6: 46279 | AL6: 46280 | AM6: 46281 | AN6: 46282 | AO6: 46283 | AP6: 46284 | AQ6: 46285 | AR6: 46286 | AS6: 46287 | AT6: 46288 | AU6: 46289 | AV6: 46290 | AW6: 46291 | AX6: 46292 | AY6: 46293 | AZ6: 46294 | BA6: 46295 | BB6: 46296 | BC6: 46297 | BD6: 46298 | BE6: 46299 | BF6: 46300 | BG6: 46301 | BH6: 46302 | BI6: 46303 | BJ6: 46304 | BK6: 46305 | BL6: 46306 | BM6: 46307 | BN6: 46308 | BO6: 46309 | BP6: 46310 | BQ6: 46311 | BR6: 46312 | BS6: 46313 | BT6: 46314 | BU6: 46315 | BV6: 46316 | BW6: 46317 | BX6: 46318 | BY6: 46319 | BZ6: 46320 | CA6: 46321 | CB6: 46322 | CC6: 46323 | CD6: 46324 | CE6: 46325 | CF6: 46326 | CG6: 46327 | CH6: 46328 | CI6: 46329 | CJ6: 46330 | CK6: 46331 | CL6: 46332 | CM6: 46333 | CN6: 46334 | CO6: 46335 | CP6: 46336 | CQ6: 46337 | CR6: 46338 | CS6: 46339 | CT6: 46340 | CU6: 46341 | CV6: 46342 | CW6: 46343 | CX6: 46344 | CY6: 46345 | CZ6: 46346 | DA6: 46347 | DB6: 46348 | DC6: 46349 | DD6: 46350 | DE6: 46351 | DF6: 46352 | DG6: 46353 | DH6: 46354 | DI6: 46355 | DJ6: 46356 | DK6: 46357 | DL6: 46358 | DM6: 46359 | DN6: 46360 | DO6: 46361 | DP6: 46362 | DQ6: 46363 | DR6: 46364 | DS6: 46365 | DT6: 46366 | DU6: 46367 | DV6: 46368 | DW6: 46369
F7: =CHOOSE(WEEKDAY(F6),"D","L","M","X","J","V","S") -> V | G7: =CHOOSE(WEEKDAY(G6),"D","L","M","X","J","V","S") -> S | H7: =CHOOSE(WEEKDAY(H6),"D","L","M","X","J","V","S") -> D | I7: =CHOOSE(WEEKDAY(I6),"D","L","M","X","J","V","S") -> L | J7: =CHOOSE(WEEKDAY(J6),"D","L","M","X","J","V","S") -> M | K7: =CHOOSE(WEEKDAY(K6),"D","L","M","X","J","V","S") -> X | L7: =CHOOSE(WEEKDAY(L6),"D","L","M","X","J","V","S") -> J | M7: =CHOOSE(WEEKDAY(M6),"D","L","M","X","J","V","S") -> V | ... DW7: =CHOOSE(WEEKDAY(DW6),"D","L","M","X","J","V","S") -> D
A8: GESTIÓN (PMBOK)
A9: G-01 | B9: Iniciación (PMBOK) | C9: 46248 | D9: 46251 | E9: =D9-C9+1 -> 4
A10: G-02 | B10: Planificación Base | C10: 46251 | D10: 46257 | E10: =D10-C10+1 -> 7
A11: G-03 | B11: Cierre y Sustentación | C11: 46363 | D11: 46369 | E11: =D11-C11+1 -> 7
A12: SPRINTS (Scrum)
A13: S0 | B13: Sprint 0 · Fundación | C13: 46251 | D13: 46257 | E13: =D13-C13+1 -> 7
A14: S1 | B14: Sprint 1 · Esqueleto Ambulante | C14: 46258 | D14: 46271 | E14: =D14-C14+1 -> 14
A15: S2 | B15: Sprint 2 · Onboarding KYC | C15: 46272 | D15: 46285 | E15: =D15-C15+1 -> 14
A16: S3 | B16: Sprint 3 · Núcleo Transaccional | C16: 46286 | D16: 46299 | E16: =D16-C16+1 -> 14
A17: S4 | B17: Sprint 4 · Transferencias | C17: 46300 | D17: 46313 | E17: =D17-C17+1 -> 14
A18: S5 | B18: Sprint 5 · Tarjeta Débito | C18: 46314 | D18: 46327 | E18: =D18-C18+1 -> 14
A19: S6 | B19: Sprint 6 · Interoperabilidad | C19: 46328 | D19: 46341 | E19: =D19-C19+1 -> 14
A20: S7 | B20: Sprint 7 · Experiencia | C20: 46342 | D20: 46355 | E20: =D20-C20+1 -> 14
A21: S8 | B21: Sprint 8 · Endurecimiento | C21: 46356 | D21: 46369 | E21: =D21-C21+1 -> 14
A22: ÉPICAS / BLOQUES DE VALOR
A23: EP-00 | B23: Iniciación y planificación | C23: 46248 | D23: 46257 | E23: =D23-C23+1 -> 10
A24: EP-01 | B24: Fundación técnica | C24: 46251 | D24: 46271 | E24: =D24-C24+1 -> 21
A25: EP-02 | B25: Identidad y onboarding KYC | C25: 46258 | D25: 46285 | E25: =D25-C25+1 -> 28
A26: EP-03 | B26: Cuentas y núcleo | C26: 46258 | D26: 46299 | E26: =D26-C26+1 -> 42
A27: EP-07 | B27: Notificaciones | C27: 46300 | D27: 46313 | E27: =D27-C27+1 -> 14
A28: EP-05 | B28: Transferencias e interop. | C28: 46300 | D28: 46341 | E28: =D28-C28+1 -> 42
A29: EP-04 | B29: Tarjeta de débito | C29: 46314 | D29: 46327 | E29: =D29-C29+1 -> 14
A30: EP-08 | B30: Multimoneda y SUNAT | C30: 46328 | D30: 46341 | E30: =D30-C30+1 -> 14
A31: EP-06 | B31: Experiencia del cliente | C31: 46342 | D31: 46355 | E31: =D31-C31+1 -> 14
A32: EP-09 | B32: Operación y observabilidad | C32: 46342 | D32: 46355 | E32: =D32-C32+1 -> 14
A33: EP-10 | B33: Calidad y cierre | C33: 46356 | D33: 46369 | E33: =D33-C33+1 -> 14
A34: HITOS DEL PROYECTO
A35: H-1 | B35: ◆ Acta de Constitución | C35: 46251 | D35: 46251 | E35: =D35-C35+1 -> 1
A36: H-2 | B36: ◆ Línea base de planificación | C36: 46257 | D36: 46257 | E36: =D36-C36+1 -> 1
A37: H-3 | B37: ◆ Integración validada | C37: 46271 | D37: 46271 | E37: =D37-C37+1 -> 1
A38: H-4 | B38: ◆ Despliegue a producción v1 | C38: 46299 | D38: 46299 | E38: =D38-C38+1 -> 1
A39: H-5 | B39: ◆ Despliegue a producción v2 | C39: 46327 | D39: 46327 | E39: =D39-C39+1 -> 1
A40: H-6 | B40: ◆ Evidencias ISO 25010 | C40: 46355 | D40: 46355 | E40: =D40-C40+1 -> 1
...

Sheet Sprints
A1: AYNI BANK — Sprints (Scrum)
A2: Sprint 0 de 1 semana + 8 sprints de 2 semanas · 17/08/2026 – 13/12/2026
A4: ID | B4: Sprint | C4: Inicio | D4: Fin | E4: Días | F4: Objetivo del sprint | G4: Épicas asociadas | H4: Hito al cierre
A5: S0 | B5: Sprint 0 · Fundación | C5: =Gantt!C13 -> 46251 | D5: =Gantt!D13 -> 46257 | E5: =Gantt!E13 -> 7 | F5: Preparar entorno, repositorios, CI/CD y backlog inicial | G5: EP-00, EP-01 | H5: —
A6: S1 | B6: Sprint 1 · Esqueleto Ambulante | C6: =Gantt!C14 -> 46258 | D6: =Gantt!D14 -> 46271 | E6: =Gantt!E14 -> 14 | F6: Walking skeleton: integración extremo a extremo | G6: EP-01, EP-02, EP-03 | H6: Integración validada
A7: S2 | B7: Sprint 2 · Onboarding KYC | C7: =Gantt!C15 -> 46272 | D7: =Gantt!D15 -> 46285 | E7: =Gantt!E15 -> 14 | F7: Alta de clientes con validación de identidad (KYC) | G7: EP-02, EP-03 | H7: —
A8: S3 | B8: Sprint 3 · Núcleo Transaccional | C8: =Gantt!C16 -> 46286 | D8: =Gantt!D16 -> 46299 | E8: =Gantt!E16 -> 14 | F8: Cuentas y motor de movimientos del core bancario | G8: EP-03 | H8: Despliegue a producción v1
A9: S4 | B9: Sprint 4 · Transferencias | C9: =Gantt!C17 -> 46300 | D9: =Gantt!D17 -> 46313 | E9: =Gantt!E17 -> 14 | F9: Transferencias entre cuentas y notificaciones | G9: EP-05, EP-07 | H9: —
A10: S5 | B10: Sprint 5 · Tarjeta Débito | C10: =Gantt!C18 -> 46314 | D10: =Gantt!D18 -> 46327 | E10: =Gantt!E18 -> 14 | F10: Emisión y gestión de tarjeta de débito | G10: EP-04, EP-05 | H10: Despliegue a producción v2
A11: S6 | B11: Sprint 6 · Interoperabilidad | C11: =Gantt!C19 -> 46328 | D11: =Gantt!D19 -> 46341 | E11: =Gantt!E19 -> 14 | F11: Interoperabilidad, multimoneda y SUNAT | G11: EP-05, EP-08 | H11: —
A12: S7 | B12: Sprint 7 · Experiencia | C12: =Gantt!C20 -> 46342 | D12: =Gantt!D20 -> 46355 | E12: =Gantt!E20 -> 14 | F12: Experiencia del cliente y observabilidad | G12: EP-06, EP-09 | H12: Evidencias ISO 25010
A13: S8 | B13: Sprint 8 · Endurecimiento | C13: =Gantt!C21 -> 46356 | D13: =Gantt!D21 -> 46369 | E13: =Gantt!E21 -> 14 | F13: Calidad, hardening, cierre y sustentación | G13: EP-10 | H13: MVP · Release 1.0.0
B15: Fechas en verde = enlazadas a la hoja Gantt (fuente única). Edita allí y aquí se actualiza.

Sheet Épicas
A1: AYNI BANK — Épicas / Bloques de valor
A2: Orden según el diagrama: por fecha de inicio y solapamiento
A4: ID | B4: Épica | C4: Inicio | D4: Fin | E4: Días | F4: Sprints que la cubren | G4: Bloque de valor
A5: EP-00 | B5: Iniciación y planificación | C5: =Gantt!C23 -> 46248 | D5: =Gantt!D23 -> 46257 | E5: =Gantt!E23 -> 10 | F5: Pre-Sprint 0 / Sprint 0 | G5: Gestión
A6: EP-01 | B6: Fundación técnica | C6: =Gantt!C24 -> 46251 | D6: =Gantt!D24 -> 46271 | E6: =Gantt!E24 -> 21 | F6: Sprint 0 – Sprint 1 | G6: Plataforma
A7: EP-02 | B7: Identidad y onboarding KYC | C7: =Gantt!C25 -> 46258 | D7: =Gantt!D25 -> 46285 | E7: =Gantt!E25 -> 28 | F7: Sprint 1 – Sprint 2 | G7: Cliente
A8: EP-03 | B8: Cuentas y núcleo | C8: =Gantt!C26 -> 46258 | D8: =Gantt!D26 -> 46299 | E8: =Gantt!E26 -> 42 | F8: Sprint 1 – Sprint 3 | G8: Core bancario
A9: EP-07 | B9: Notificaciones | C9: =Gantt!C27 -> 46300 | D9: =Gantt!D27 -> 46313 | E9: =Gantt!E27 -> 14 | F9: Sprint 4 | G9: Cliente
A10: EP-05 | B10: Transferencias e interop. | C10: =Gantt!C28 -> 46300 | D10: =Gantt!D28 -> 46341 | E10: =Gantt!E28 -> 42 | F10: Sprint 4 – Sprint 6 | G10: Core bancario
A11: EP-04 | B11: Tarjeta de débito | C11: =Gantt!C29 -> 46314 | D11: =Gantt!D29 -> 46327 | E11: =Gantt!E29 -> 14 | F11: Sprint 5 | G11: Producto
A12: EP-08 | B12: Multimoneda y SUNAT | C12: =Gantt!C30 -> 46328 | D12: =Gantt!D30 -> 46341 | E12: =Gantt!E30 -> 14 | F12: Sprint 6 | G12: Cumplimiento
A13: EP-06 | B13: Experiencia del cliente | C13: =Gantt!C31 -> 46342 | D13: =Gantt!D31 -> 46355 | E13: =Gantt!E31 -> 14 | F13: Sprint 7 | G13: Cliente
A14: EP-09 | B14: Operación y observabilidad | C14: =Gantt!C32 -> 46342 | D14: =Gantt!D32 -> 46355 | E14: =Gantt!E32 -> 14 | F14: Sprint 7 | G14: Plataforma
A15: EP-10 | B15: Calidad y cierre | C15: =Gantt!C33 -> 46356 | D15: =Gantt!D33 -> 46369 | E15: =Gantt!E33 -> 14 | F15: Sprint 8 | G15: Gestión
B17: Fechas en verde = enlazadas a la hoja Gantt (fuente única). Edita allí y aquí se actualiza.
